<sdf version="1.6">
  <model name="my_model">
    <gazebo>
      <plugin name="gazebo_ros_control" filename="libgazebo_ros_control.so">
        <robotNamespace>/my_model</robotNamespace>
      </plugin>
    </gazebo>
    
      <static>false</static>
      <!-- base link -->
      <link name="link_0">
        <static>false</static>
        <pose>0 0 0 0 0 0</pose>
        
        <inertial>
          <mass>100</mass>
          <inertia> <!-- inertias are tricky to compute -->
            <!-- http://gazebosim.org/tutorials?tut=inertia&cat=build_robot -->
            <ixx>8.3</ixx>       <!-- for a box: ixx = 0.083 * mass * (y*y + z*z) -->
            <ixy>0.0</ixy>         <!-- for a box: ixy = 0 -->
            <ixz>0.0</ixz>         <!-- for a box: ixz = 0 -->
            <iyy>8.3</iyy>       <!-- for a box: iyy = 0.083 * mass * (x*x + z*z) -->
            <iyz>0.0</iyz>         <!-- for a box: iyz = 0 -->
            <izz>8.3</izz>       <!-- for a box: izz = 0.083 * mass * (x*x + y*y) -->
          </inertia>
        </inertial>
        <collision name="collision">
          <geometry>
            <box>
              <size>1 1 1</size>
            </box>
          </geometry>
        </collision>
        <visual name="visual">
          <geometry>
            <box>
              <size>1 1 1</size>
            </box>
          </geometry>
        </visual>
      </link>

      <link name="link_1">
        <pose>0 0 2.25 0 0 0</pose>
        <static>false</static>
        <inertial>
          <mass>1.0</mass>
          <inertia> <!-- inertias are tricky to compute -->
            <!-- http://gazebosim.org/tutorials?tut=inertia&cat=build_robot -->
            <ixx>0.01266</ixx>       <!-- for a box: ixx = 0.083 * mass * (y*y + z*z) -->
            <ixy>0.0</ixy>           <!-- for a box: ixy = 0 -->
            <ixz>0.0</ixz>           <!-- for a box: ixz = 0 -->
            <iyy>0.01266</iyy>       <!-- for a box: iyy = 0.083 * mass * (x*x + z*z) -->
            <iyz>0.0</iyz>           <!-- for a box: iyz = 0 -->
            <izz>0.01038</izz>       <!-- for a box: izz = 0.083 * mass * (x*x + y*y) -->
          </inertia>
        </inertial>
        <collision name="link_1_coll">
          <geometry>
            <box>
              <size>0.25 0.25 3</size>
            </box>
          </geometry>
        </collision>
        <visual name="link_1_vis">
          <geometry>
            <box>
              <size>0.25 0.25 3</size>
            </box>
          </geometry>
        </visual>
      </link>

      <joint name="joint_1" type="revolute">
        <pose>0 0 -1.5 0 0 0</pose>
        <parent>link_0</parent>
        <child>link_1</child>
        <axis>
          <xyz>0 1 0</xyz>
          <limit>
            <lower>-1.57</lower> <!-- -90 degrees -->
            <upper>1.57</upper>  <!-- 90 degrees -->
          </limit>
        </axis>
      </joint>

      <transmission name="tran1">
        <type>transmission_interface/SimpleTransmission</type>
        <joint name="joint_1"/>
        <actuator name="motor1">
          <hardwareInterface>EffortJointInterface</hardwareInterface>
          <mechanicalReduction>1</mechanicalReduction>
        </actuator>
      </transmission>
    </model>
</sdf>
